Workbook

Sheet Номенклатура
A1: =IFERROR(__xludf.DUMMYFUNCTION("ARRAYFORMULA(IMPORTRANGE(""https://docs.google.com/spreadsheets/d/1iWfgTn_Pi02Cgzvv2hNxbn5R87Czwggoktc9asHRCjo/"",""Номенклатура!A1:BG1000""))"),"Номер") -> Номер | B1: =IFERROR(__xludf.DUMMYFUNCTION("""COMPUTED_VALUE"""),"Описание") -> Описание | C1: =IFERROR(__xludf.DUMMYFUNCTION("""COMPUTED_VALUE"""),"Цена на ал в 1 бр.") -> Цена на ал в 1 бр. | D1: =IFERROR(__xludf.DUMMYFUNCTION("""COMPUTED_VALUE"""),"Премахване на 0-лите") -> Премахване на 0-лите | E1: =IFERROR(__xludf.DUMMYFUNCTION("""COMPUTED_VALUE"""),"Процент АЛ в детайл") -> Процент АЛ в детайл | F1: =IFERROR(__xludf.DUMMYFUNCTION("""COMPUTED_VALUE"""),"Видове АL") -> Видове АL
F2: =IFERROR(__xludf.DUMMYFUNCTION("""COMPUTED_VALUE"""),"Вид AL за тялото") -> Вид AL за тялото | G2: =IFERROR(__xludf.DUMMYFUNCTION("""COMPUTED_VALUE"""),"Тегло") -> Тегло | H2: =IFERROR(__xludf.DUMMYFUNCTION("""COMPUTED_VALUE"""),"Цена") -> Цена | I2: =IFERROR(__xludf.DUMMYFUNCTION("""COMPUTED_VALUE"""),"Вид AL за Пр. Капаци") -> Вид AL за Пр. Капаци | J2: =IFERROR(__xludf.DUMMYFUNCTION("""COMPUTED_VALUE"""),"Тегло") -> Тегло | K2: =IFERROR(__xludf.DUMMYFUNCTION("""COMPUTED_VALUE"""),"Цена") -> Цена | L2: =IFERROR(__xludf.DUMMYFUNCTION("""COMPUTED_VALUE"""),"Вид AL за З.Капаци") -> Вид AL за З.Капаци | M2: =IFERROR(__xludf.DUMMYFUNCTION("""COMPUTED_VALUE"""),"Тегло") -> Тегло | N2: =IFERROR(__xludf.DUMMYFUNCTION("""COMPUTED_VALUE"""),"Цена") -> Цена | P2: =IFERROR(__xludf.DUMMYFUNCTION("""COMPUTED_VALUE"""),"R Вар. 25 (0.21 .107BGN/unit- .kg/unit; 2.904BGN/unit- .kg/unit; 0.317 .BGN/unit- .kg/unit)") -> R Вар. 25 (0.21 .107BGN/unit- .kg/unit; 2.904BGN/unit- .kg/unit; 0.317 .BGN/unit- .kg/unit)
A3: =IFERROR(__xludf.DUMMYFUNCTION("""COMPUTED_VALUE"""),"575-60044") -> 575-60044 | B3: =IFERROR(__xludf.DUMMYFUNCTION("""COMPUTED_VALUE"""),"DC60 Multiturn Body 3/8'' shaft; Nitrile seal Sq. Flange Side PG9 conn") -> DC60 Multiturn Body 3/8'' shaft; Nitrile seal Sq. Flange Side PG9 conn | C3: =IFERROR(__xludf.DUMMYFUNCTION("""COMPUTED_VALUE"""),2.9035) -> 2.9035 | D3: =IFERROR(__xludf.DUMMYFUNCTION("""COMPUTED_VALUE"""),2.9035) -> 2.9035 | E3: =IFERROR(__xludf.DUMMYFUNCTION("""COMPUTED_VALUE"""),"") | F3: =IFERROR(__xludf.DUMMYFUNCTION("""COMPUTED_VALUE"""),"Ф62 AL 2017 Italy") -> Ф62 AL 2017 Italy | G3: =IFERROR(__xludf.DUMMYFUNCTION("""COMPUTED_VALUE"""),0.21) -> 0.21 | H3: =IFERROR(__xludf.DUMMYFUNCTION("""COMPUTED_VALUE"""),2.7216) -> 2.7216 | I3: =IFERROR(__xludf.DUMMYFUNCTION("""COMPUTED_VALUE"""),"AL USA (pc.)") -> AL USA (pc.) | J3: =IFERROR(__xludf.DUMMYFUNCTION("""COMPUTED_VALUE"""),0.107) -> 0.107 | K3: =IFERROR(__xludf.DUMMYFUNCTION("""COMPUTED_VALUE"""),0.18189999999999998) -> 0.1819 | L3: =IFERROR(__xludf.DUMMYFUNCTION("""COMPUTED_VALUE"""),"") | M3: =IFERROR(__xludf.DUMMYFUNCTION("""COMPUTED_VALUE"""),"") | N3: =IFERROR(__xludf.DUMMYFUNCTION("""COMPUTED_VALUE"""),"")
A4: =IFERROR(__xludf.DUMMYFUNCTION("""COMPUTED_VALUE"""),"575-91001-9") -> 575-91001-9 | B4: =IFERROR(__xludf.DUMMYFUNCTION("""COMPUTED_VALUE"""),"DC25FS </= 9 min IP69Kw hole on shaft no knurl M12 side conn. HARSCO") -> DC25FS </= 9 min IP69Kw hole on shaft no knurl M12 side conn. HARSCO | C4: =IFERROR(__xludf.DUMMYFUNCTION("""COMPUTED_VALUE"""),3.94836) -> 3.94836 | D4: =IFERROR(__xludf.DUMMYFUNCTION("""COMPUTED_VALUE"""),3.94836) -> 3.94836 | E4: =IFERROR(__xludf.DUMMYFUNCTION("""COMPUTED_VALUE"""),"") | F4: =IFERROR(__xludf.DUMMYFUNCTION("""COMPUTED_VALUE"""),"Ф65 AL 2017 Italy") -> Ф65 AL 2017 Italy | G4: =IFERROR(__xludf.DUMMYFUNCTION("""COMPUTED_VALUE"""),0.234) -> 0.234 | H4: =IFERROR(__xludf.DUMMYFUNCTION("""COMPUTED_VALUE"""),3.0326400000000002) -> 3.03264 | I4: =IFERROR(__xludf.DUMMYFUNCTION("""COMPUTED_VALUE"""),"AL USA") -> AL USA | J4: =IFERROR(__xludf.DUMMYFUNCTION("""COMPUTED_VALUE"""),0.066) -> 0.066 | K4: =IFERROR(__xludf.DUMMYFUNCTION("""COMPUTED_VALUE"""),0.11220000000000001) -> 0.1122 | L4: =IFERROR(__xludf.DUMMYFUNCTION("""COMPUTED_VALUE"""),"Ф65 AL 2017 Italy") -> Ф65 AL 2017 Italy | M4: =IFERROR(__xludf.DUMMYFUNCTION("""COMPUTED_VALUE"""),0.062) -> 0.062 | N4: =IFERROR(__xludf.DUMMYFUNCTION("""COMPUTED_VALUE"""),0.80352) -> 0.80352
A5: =IFERROR(__xludf.DUMMYFUNCTION("""COMPUTED_VALUE"""),"575-92015") -> 575-92015 | B5: =IFERROR(__xludf.DUMMYFUNCTION("""COMPUTED_VALUE"""),"DC25FE, Multiturn Body 5/8"" shaft flange end conn.") -> DC25FE, Multiturn Body 5/8" shaft flange end conn. | C5: =IFERROR(__xludf.DUMMYFUNCTION("""COMPUTED_VALUE"""),3.4419000000000004) -> 3.4419 | D5: =IFERROR(__xludf.DUMMYFUNCTION("""COMPUTED_VALUE"""),3.4419000000000004) -> 3.4419 | E5: =IFERROR(__xludf.DUMMYFUNCTION("""COMPUTED_VALUE"""),"") | F5: =IFERROR(__xludf.DUMMYFUNCTION("""COMPUTED_VALUE"""),"Ф65 AL 2017 Italy") -> Ф65 AL 2017 Italy | G5: =IFERROR(__xludf.DUMMYFUNCTION("""COMPUTED_VALUE"""),0.24) -> 0.24 | H5: =IFERROR(__xludf.DUMMYFUNCTION("""COMPUTED_VALUE"""),3.1104000000000003) -> 3.1104 | I5: =IFERROR(__xludf.DUMMYFUNCTION("""COMPUTED_VALUE"""),"AL USA") -> AL USA | J5: =IFERROR(__xludf.DUMMYFUNCTION("""COMPUTED_VALUE"""),0.195) -> 0.195 | K5: =IFERROR(__xludf.DUMMYFUNCTION("""COMPUTED_VALUE"""),0.3315) -> 0.3315 | L5: =IFERROR(__xludf.DUMMYFUNCTION("""COMPUTED_VALUE"""),"") | M5: =IFERROR(__xludf.DUMMYFUNCTION("""COMPUTED_VALUE"""),"") | N5: =IFERROR(__xludf.DUMMYFUNCTION("""COMPUTED_VALUE"""),"")
A6: =IFERROR(__xludf.DUMMYFUNCTION("""COMPUTED_VALUE"""),"575-93001") -> 575-93001 | B6: =IFERROR(__xludf.DUMMYFUNCTION("""COMPUTED_VALUE"""),"H25 Resolver Shaft 5/8"" With MS-16 side conn. w/o seal Short body") -> H25 Resolver Shaft 5/8" With MS-16 side conn. w/o seal Short body | C6: =IFERROR(__xludf.DUMMYFUNCTION("""COMPUTED_VALUE"""),2.0628) -> 2.0628 | D6: =IFERROR(__xludf.DUMMYFUNCTION("""COMPUTED_VALUE"""),2.0628) -> 2.0628 | E6: =IFERROR(__xludf.DUMMYFUNCTION("""COMPUTED_VALUE"""),"") | F6: =IFERROR(__xludf.DUMMYFUNCTION("""COMPUTED_VALUE"""),"Cast AL Bulgaria (pc.)") -> Cast AL Bulgaria (pc.) | G6: =IFERROR(__xludf.DUMMYFUNCTION("""COMPUTED_VALUE"""),0.213) -> 0.213 | H6: =IFERROR(__xludf.DUMMYFUNCTION("""COMPUTED_VALUE"""),0.99258) -> 0.99258 | I6: =IFERROR(__xludf.DUMMYFUNCTION("""COMPUTED_VALUE"""),"AL USA") -> AL USA | J6: =IFERROR(__xludf.DUMMYFUNCTION("""COMPUTED_VALUE"""),0.195) -> 0.195 | K6: =IFERROR(__xludf.DUMMYFUNCTION("""COMPUTED_VALUE"""),0.3315) -> 0.3315 | L6: =IFERROR(__xludf.DUMMYFUNCTION("""COMPUTED_VALUE"""),"Ф65 AL 2017 Italy") -> Ф65 AL 2017 Italy | M6: =IFERROR(__xludf.DUMMYFUNCTION("""COMPUTED_VALUE"""),0.057) -> 0.057 | N6: =IFERROR(__xludf.DUMMYFUNCTION("""COMPUTED_VALUE"""),0.73872) -> 0.73872
A7: =IFERROR(__xludf.DUMMYFUNCTION("""COMPUTED_VALUE"""),"H25-FE-06") -> H25-FE-06 | B7: =IFERROR(__xludf.DUMMYFUNCTION("""COMPUTED_VALUE"""),"Transducer 1 Turn Flange Mntaligned at zero degrees With 3mm Key Way, 3/8""shaft") -> Transducer 1 Turn Flange Mntaligned at zero degrees With 3mm Key Way, 3/8"shaft | C7: =IFERROR(__xludf.DUMMYFUNCTION("""COMPUTED_VALUE"""),4.14956) -> 4.14956 | D7: =IFERROR(__xludf.DUMMYFUNCTION("""COMPUTED_VALUE"""),4.14956) -> 4.14956 | E7: =IFERROR(__xludf.DUMMYFUNCTION("""COMPUTED_VALUE"""),"") | F7: =IFERROR(__xludf.DUMMYFUNCTION("""COMPUTED_VALUE"""),"Ф65 AL 2017 Italy") -> Ф65 AL 2017 Italy | G7: =IFERROR(__xludf.DUMMYFUNCTION("""COMPUTED_VALUE"""),0.311) -> 0.311 | H7: =IFERROR(__xludf.DUMMYFUNCTION("""COMPUTED_VALUE"""),4.03056) -> 4.03056 | I7: =IFERROR(__xludf.DUMMYFUNCTION("""COMPUTED_VALUE"""),"AL USA (pc.)") -> AL USA (pc.) | J7: =IFERROR(__xludf.DUMMYFUNCTION("""COMPUTED_VALUE"""),0.07) -> 0.07 | K7: =IFERROR(__xludf.DUMMYFUNCTION("""COMPUTED_VALUE"""),0.11900000000000001) -> 0.119 | L7: =IFERROR(__xludf.DUMMYFUNCTION("""COMPUTED_VALUE"""),"") | M7: =IFERROR(__xludf.DUMMYFUNCTION("""COMPUTED_VALUE"""),"") | N7: =IFERROR(__xludf.DUMMYFUNCTION("""COMPUTED_VALUE"""),"")
A8: =IFERROR(__xludf.DUMMYFUNCTION("""COMPUTED_VALUE"""),"H25-FE") -> H25-FE | B8: =IFERROR(__xludf.DUMMYFUNCTION("""COMPUTED_VALUE"""),"Size 25 resolver 3/8"" shaft Flange mount End connector 0.95 TR @ 5000 Hz") -> Size 25 resolver 3/8" shaft Flange mount End connector 0.95 TR @ 5000 Hz | C8: =IFERROR(__xludf.DUMMYFUNCTION("""COMPUTED_VALUE"""),4.14956) -> 4.14956 | D8: =IFERROR(__xludf.DUMMYFUNCTION("""COMPUTED_VALUE"""),4.14956) -> 4.14956 | E8: =IFERROR(__xludf.DUMMYFUNCTION("""COMPUTED_VALUE"""),"") | F8: =IFERROR(__xludf.DUMMYFUNCTION("""COMPUTED_VALUE"""),"Ф65 AL 2017 Italy") -> Ф65 AL 2017 Italy | G8: =IFERROR(__xludf.DUMMYFUNCTION("""COMPUTED_VALUE"""),0.311) -> 0.311 | H8: =IFERROR(__xludf.DUMMYFUNCTION("""COMPUTED_VALUE"""),4.03056) -> 4.03056 | I8: =IFERROR(__xludf.DUMMYFUNCTION("""COMPUTED_VALUE"""),"AL USA (pc.)") -> AL USA (pc.) | J8: =IFERROR(__xludf.DUMMYFUNCTION("""COMPUTED_VALUE"""),0.07) -> 0.07 | K8: =IFERROR(__xludf.DUMMYFUNCTION("""COMPUTED_VALUE"""),0.11900000000000001) -> 0.119 | L8: =IFERROR(__xludf.DUMMYFUNCTION("""COMPUTED_VALUE"""),"") | M8: =IFERROR(__xludf.DUMMYFUNCTION("""COMPUTED_VALUE"""),"") | N8: =IFERROR(__xludf.DUMMYFUNCTION("""COMPUTED_VALUE"""),"")
A9: =IFERROR(__xludf.DUMMYFUNCTION("""COMPUTED_VALUE"""),"575-60007") -> 575-60007 | B9: =IFERROR(__xludf.DUMMYFUNCTION("""COMPUTED_VALUE"""),"NR-60 Multi Body 10mm shaft Nitrile seal Square flange End conn.") -> NR-60 Multi Body 10mm shaft Nitrile seal Square flange End conn. | C9: =IFERROR(__xludf.DUMMYFUNCTION("""COMPUTED_VALUE"""),2.9812600000000002) -> 2.98126 | D9: =IFERROR(__xludf.DUMMYFUNCTION("""COMPUTED_VALUE"""),2.9812600000000002) -> 2.98126 | E9: =IFERROR(__xludf.DUMMYFUNCTION("""COMPUTED_VALUE"""),"") | F9: =IFERROR(__xludf.DUMMYFUNCTION("""COMPUTED_VALUE"""),"Ф62 AL 2017 Italy") -> Ф62 AL 2017 Italy | G9: =IFERROR(__xludf.DUMMYFUNCTION("""COMPUTED_VALUE"""),0.216) -> 0.216 | H9: =IFERROR(__xludf.DUMMYFUNCTION("""COMPUTED_VALUE"""),2.79936) -> 2.79936 | I9: =IFERROR(__xludf.DUMMYFUNCTION("""COMPUTED_VALUE"""),"AL USA (pc.)") -> AL USA (pc.) | J9: =IFERROR(__xludf.DUMMYFUNCTION("""COMPUTED_VALUE"""),0.107) -> 0.107 | K9: =IFERROR(__xludf.DUMMYFUNCTION("""COMPUTED_VALUE"""),0.18189999999999998) -> 0.1819 | L9: =IFERROR(__xludf.DUMMYFUNCTION("""COMPUTED_VALUE"""),"") | M9: =IFERROR(__xludf.DUMMYFUNCTION("""COMPUTED_VALUE"""),"") | N9: =IFERROR(__xludf.DUMMYFUNCTION("""COMPUTED_VALUE"""),"")
A10: =IFERROR(__xludf.DUMMYFUNCTION("""COMPUTED_VALUE"""),"575-91001") -> 575-91001 | B10: =IFERROR(__xludf.DUMMYFUNCTION("""COMPUTED_VALUE"""),"DC25FE </= 9 min 3/8"" sahft flange end conn.") -> DC25FE </= 9 min 3/8" sahft flange end conn. | C10: =IFERROR(__xludf.DUMMYFUNCTION("""COMPUTED_VALUE"""),3.3849200000000006) -> 3.38492 | D10: =IFERROR(__xludf.DUMMYFUNCTION("""COMPUTED_VALUE"""),3.3849200000000006) -> 3.38492 | E10: =IFERROR(__xludf.DUMMYFUNCTION("""COMPUTED_VALUE"""),"") | F10: =IFERROR(__xludf.DUMMYFUNCTION("""COMPUTED_VALUE"""),"Ф65 AL 2017 Italy") -> Ф65 AL 2017 Italy | G10: =IFERROR(__xludf.DUMMYFUNCTION("""COMPUTED_VALUE"""),0.252) -> 0.252 | H10: =IFERROR(__xludf.DUMMYFUNCTION("""COMPUTED_VALUE"""),3.2659200000000004) -> 3.26592 | I10: =IFERROR(__xludf.DUMMYFUNCTION("""COMPUTED_VALUE"""),"AL USA (pc.)") -> AL USA (pc.) | J10: =IFERROR(__xludf.DUMMYFUNCTION("""COMPUTED_VALUE"""),0.07) -> 0.07 | K10: =IFERROR(__xludf.DUMMYFUNCTION("""COMPUTED_VALUE"""),0.11900000000000001) -> 0.119 | L10: =IFERROR(__xludf.DUMMYFUNCTION("""COMPUTED_VALUE"""),"") | M10: =IFERROR(__xludf.DUMMYFUNCTION("""COMPUTED_VALUE"""),"") | N10: =IFERROR(__xludf.DUMMYFUNCTION("""COMPUTED_VALUE"""),"")
A11: =IFERROR(__xludf.DUMMYFUNCTION("""COMPUTED_VALUE"""),"575-92000") -> 575-92000 | B11: =IFERROR(__xludf.DUMMYFUNCTION("""COMPUTED_VALUE"""),"DC25FS Multiturn Body 3/8"" shaft Flange Multiturn Body 3/8"" shaft MS23 side conn") -> DC25FS Multiturn Body 3/8" shaft Flange Multiturn Body 3/8" shaft MS23 side conn | C11: =IFERROR(__xludf.DUMMYFUNCTION("""COMPUTED_VALUE"""),1.1675) -> 1.1675 | D11: =IFERROR(__xludf.DUMMYFUNCTION("""COMPUTED_VALUE"""),1.1675) -> 1.1675 | E11: =IFERROR(__xludf.DUMMYFUNCTION("""COMPUTED_VALUE"""),"") | F11: =IFERROR(__xludf.DUMMYFUNCTION("""COMPUTED_VALUE"""),"Cast AL Bulgaria (pc.)") -> Cast AL Bulgaria (pc.) | G11: =IFERROR(__xludf.DUMMYFUNCTION("""COMPUTED_VALUE"""),0.225) -> 0.225 | H11: =IFERROR(__xludf.DUMMYFUNCTION("""COMPUTED_VALUE"""),1.0485) -> 1.0485 | I11: =IFERROR(__xludf.DUMMYFUNCTION("""COMPUTED_VALUE"""),"AL USA (pc.)") -> AL USA (pc.) | J11: =IFERROR(__xludf.DUMMYFUNCTION("""COMPUTED_VALUE"""),0.07) -> 0.07 | K11: =IFERROR(__xludf.DUMMYFUNCTION("""COMPUTED_VALUE"""),0.11900000000000001) -> 0.119 | L11: =IFERROR(__xludf.DUMMYFUNCTION("""COMPUTED_VALUE"""),"") | M11: =IFERROR(__xludf.DUMMYFUNCTION("""COMPUTED_VALUE"""),"") | N11: =IFERROR(__xludf.DUMMYFUNCTION("""COMPUTED_VALUE"""),"")
A12: =IFERROR(__xludf.DUMMYFUNCTION("""COMPUTED_VALUE"""),"575-92006") -> 575-92006 | B12: =IFERROR(__xludf.DUMMYFUNCTION("""COMPUTED_VALUE"""),"DC25FE </= 9 min 5/8"" shaft flange end conn") -> DC25FE </= 9 min 5/8" shaft flange end conn | C12: =IFERROR(__xludf.DUMMYFUNCTION("""COMPUTED_VALUE"""),3.5974200000000005) -> 3.59742 | D12: =IFERROR(__xludf.DUMMYFUNCTION("""COMPUTED_VALUE"""),3.5974200000000005) -> 3.59742 | E12: =IFERROR(__xludf.DUMMYFUNCTION("""COMPUTED_VALUE"""),"") | F12: =IFERROR(__xludf.DUMMYFUNCTION("""COMPUTED_VALUE"""),"Ф65 AL 2017 Italy") -> Ф65 AL 2017 Italy | G12: =IFERROR(__xludf.DUMMYFUNCTION("""COMPUTED_VALUE"""),0.252) -> 0.252 | H12: =IFERROR(__xludf.DUMMYFUNCTION("""COMPUTED_VALUE"""),3.2659200000000004) -> 3.26592 | I12: =IFERROR(__xludf.DUMMYFUNCTION("""COMPUTED_VALUE"""),"AL USA") -> AL USA | J12: =IFERROR(__xludf.DUMMYFUNCTION("""COMPUTED_VALUE"""),0.195) -> 0.195 | K12: =IFERROR(__xludf.DUMMYFUNCTION("""COMPUTED_VALUE"""),0.3315) -> 0.3315 | L12: =IFERROR(__xludf.DUMMYFUNCTION("""COMPUTED_VALUE"""),"") | M12: =IFERROR(__xludf.DUMMYFUNCTION("""COMPUTED_VALUE"""),"") | N12: =IFERROR(__xludf.DUMMYFUNCTION("""COMPUTED_VALUE"""),"")
A13: =IFERROR(__xludf.DUMMYFUNCTION("""COMPUTED_VALUE"""),"DC25-2FE") -> DC25-2FE | B13: =IFERROR(__xludf.DUMMYFUNCTION("""COMPUTED_VALUE"""),"DC25 Housing 2Sp. End conn. 3/8"" shaft ") -> DC25 Housing 2Sp. End conn. 3/8" shaft | C13: =IFERROR(__xludf.DUMMYFUNCTION("""COMPUTED_VALUE"""),3.3849200000000006) -> 3.38492 | D13: =IFERROR(__xludf.DUMMYFUNCTION("""COMPUTED_VALUE"""),3.3849200000000006) -> 3.38492 | E13: =IFERROR(__xludf.DUMMYFUNCTION("""COMPUTED_VALUE"""),"") | F13: =IFERROR(__xludf.DUMMYFUNCTION("""COMPUTED_VALUE"""),"Ф65 AL 2017 Italy") -> Ф65 AL 2017 Italy | G13: =IFERROR(__xludf.DUMMYFUNCTION("""COMPUTED_VALUE"""),0.252) -> 0.252 | H13: =IFERROR(__xludf.DUMMYFUNCTION("""COMPUTED_VALUE"""),3.2659200000000004) -> 3.26592 | I13: =IFERROR(__xludf.DUMMYFUNCTION("""COMPUTED_VALUE"""),"AL USA (pc.)") -> AL USA (pc.) | J13: =IFERROR(__xludf.DUMMYFUNCTION("""COMPUTED_VALUE"""),0.07) -> 0.07 | K13: =IFERROR(__xludf.DUMMYFUNCTION("""COMPUTED_VALUE"""),0.11900000000000001) -> 0.119 | L13: =IFERROR(__xludf.DUMMYFUNCTION("""COMPUTED_VALUE"""),"") | M13: =IFERROR(__xludf.DUMMYFUNCTION("""COMPUTED_VALUE"""),"") | N13: =IFERROR(__xludf.DUMMYFUNCTION("""COMPUTED_VALUE"""),"")
A14: =IFERROR(__xludf.DUMMYFUNCTION("""COMPUTED_VALUE"""),"H25-F1E") -> H25-F1E | B14: =IFERROR(__xludf.DUMMYFUNCTION("""COMPUTED_VALUE"""),"Transducer 1 Turn C&A Flange TR=0/95; 5KHz end conn.") -> Transducer 1 Turn C&A Flange TR=0/95; 5KHz end conn. | C14: =IFERROR(__xludf.DUMMYFUNCTION("""COMPUTED_VALUE"""),31.05216) -> 31.05216 | D14: =IFERROR(__xludf.DUMMYFUNCTION("""COMPUTED_VALUE"""),31.05216) -> 31.05216 | E14: =IFERROR(__xludf.DUMMYFUNCTION("""COMPUTED_VALUE"""),"") | F14: =IFERROR(__xludf.DUMMYFUNCTION("""COMPUTED_VALUE"""),"Ф65 AL 2017 Italy") -> Ф65 AL 2017 Italy | G14: =IFERROR(__xludf.DUMMYFUNCTION("""COMPUTED_VALUE"""),0.311) -> 0.311 | H14: =IFERROR(__xludf.DUMMYFUNCTION("""COMPUTED_VALUE"""),4.03056) -> 4.03056 | I14: =IFERROR(__xludf.DUMMYFUNCTION("""COMPUTED_VALUE"""),"Ф65 AL 2017 Italy") -> Ф65 AL 2017 Italy | J14: =IFERROR(__xludf.DUMMYFUNCTION("""COMPUTED_VALUE"""),0.087) -> 0.087 | K14: =IFERROR(__xludf.DUMMYFUNCTION("""COMPUTED_VALUE"""),1.12752) -> 1.12752 | L14: =IFERROR(__xludf.DUMMYFUNCTION("""COMPUTED_VALUE"""),"кв.80 AL2017 Italy") -> кв.80 AL2017 Italy | M14: =IFERROR(__xludf.DUMMYFUNCTION("""COMPUTED_VALUE"""),0.111) -> 0.111 | N14: =IFERROR(__xludf.DUMMYFUNCTION("""COMPUTED_VALUE"""),25.89408) -> 25.89408
A15: =IFERROR(__xludf.DUMMYFUNCTION("""COMPUTED_VALUE"""),"H25-FS-06") -> H25-FS-06 | B15: =IFERROR(__xludf.DUMMYFUNCTION("""COMPUTED_VALUE"""),"Size 25 resolver 3/8"" shaft Flange mount Side connector w/3 mm keyway") -> Size 25 resolver 3/8" shaft Flange mount Side connector w/3 mm keyway | C15: =IFERROR(__xludf.DUMMYFUNCTION("""COMPUTED_VALUE"""),1.8503) -> 1.8503 | D15: =IFERROR(__xludf.DUMMYFUNCTION("""COMPUTED_VALUE"""),1.8503) -> 1.8503 | E15: =IFERROR(__xludf.DUMMYFUNCTION("""COMPUTED_VALUE"""),"") | F15: =IFERROR(__xludf.DUMMYFUNCTION("""COMPUTED_VALUE"""),"Cast AL Bulgaria (pc.)") -> Cast AL Bulgaria (pc.) | G15: =IFERROR(__xludf.DUMMYFUNCTION("""COMPUTED_VALUE"""),0.213) -> 0.213 | H15: =IFERROR(__xludf.DUMMYFUNCTION("""COMPUTED_VALUE"""),0.99258) -> 0.99258 | I15: =IFERROR(__xludf.DUMMYFUNCTION("""COMPUTED_VALUE"""),"AL USA (pc.)") -> AL USA (pc.) | J15: =IFERROR(__xludf.DUMMYFUNCTION("""COMPUTED_VALUE"""),0.07) -> 0.07 | K15: =IFERROR(__xludf.DUMMYFUNCTION("""COMPUTED_VALUE"""),0.11900000000000001) -> 0.119 | L15: =IFERROR(__xludf.DUMMYFUNCTION("""COMPUTED_VALUE"""),"Ф65 AL 2017 Italy") -> Ф65 AL 2017 Italy | M15: =IFERROR(__xludf.DUMMYFUNCTION("""COMPUTED_VALUE"""),0.057) -> 0.057 | N15: =IFERROR(__xludf.DUMMYFUNCTION("""COMPUTED_VALUE"""),0.73872) -> 0.73872
A16: =IFERROR(__xludf.DUMMYFUNCTION("""COMPUTED_VALUE"""),"H25-SE") -> H25-SE | B16: =IFERROR(__xludf.DUMMYFUNCTION("""COMPUTED_VALUE"""),"Size 25 resolver 3/8"" shaft servo mount End connector 0.95 0.95 T.R. @5000 Hz") -> Size 25 resolver 3/8" shaft servo mount End connector 0.95 0.95 T.R. @5000 Hz | C16: =IFERROR(__xludf.DUMMYFUNCTION("""COMPUTED_VALUE"""),4.717440000000001) -> 4.71744 | D16: =IFERROR(__xludf.DUMMYFUNCTION("""COMPUTED_VALUE"""),4.717440000000001) -> 4.71744 | E16: =IFERROR(__xludf.DUMMYFUNCTION("""COMPUTED_VALUE"""),"") | F16: =IFERROR(__xludf.DUMMYFUNCTION("""COMPUTED_VALUE"""),"Ф65 AL 2017 Italy") -> Ф65 AL 2017 Italy | G16: =IFERROR(__xludf.DUMMYFUNCTION("""COMPUTED_VALUE"""),0.311) -> 0.311 | H16: =IFERROR(__xludf.DUMMYFUNCTION("""COMPUTED_VALUE"""),4.03056) -> 4.03056 | I16: =IFERROR(__xludf.DUMMYFUNCTION("""COMPUTED_VALUE"""),"Ф65 AL 2017 Italy") -> Ф65 AL 2017 Italy | J16: =IFERROR(__xludf.DUMMYFUNCTION("""COMPUTED_VALUE"""),0.053) -> 0.053 | K16: =IFERROR(__xludf.DUMMYFUNCTION("""COMPUTED_VALUE"""),0.68688) -> 0.68688 | L16: =IFERROR(__xludf.DUMMYFUNCTION("""COMPUTED_VALUE"""),"") | M16: =IFERROR(__xludf.DUMMYFUNCTION("""COMPUTED_VALUE"""),"") | N16: =IFERROR(__xludf.DUMMYFUNCTION("""COMPUTED_VALUE"""),"")
A17: =IFERROR(__xludf.DUMMYFUNCTION("""COMPUTED_VALUE"""),"575-60021") -> 575-60021 | B17: =IFERROR(__xludf.DUMMYFUNCTION("""COMPUTED_VALUE"""),"NR-60 Encoder Avago assembly,10 mm, multiturn shaft, servo mount, for SIDE CONNECTORS") -> NR-60 Encoder Avago assembly,10 mm, multiturn shaft, servo mount, for SIDE CONNECTORS | C17: =IFERROR(__xludf.DUMMYFUNCTION("""COMPUTED_VALUE"""),2.4499) -> 2.4499 | D17: =IFERROR(__xludf.DUMMYFUNCTION("""COMPUTED_VALUE"""),2.4499) -> 2.4499 | E17: =IFERROR(__xludf.DUMMYFUNCTION("""COMPUTED_VALUE"""),"") | F17: =IFERROR(__xludf.DUMMYFUNCTION("""COMPUTED_VALUE"""),"Ф62 AL 2017 Italy") -> Ф62 AL 2017 Italy | G17: =IFERROR(__xludf.DUMMYFUNCTION("""COMPUTED_VALUE"""),0.175) -> 0.175 | H17: =IFERROR(__xludf.DUMMYFUNCTION("""COMPUTED_VALUE"""),2.268) -> 2.268 | I17: =IFERROR(__xludf.DUMMYFUNCTION("""COMPUTED_VALUE"""),"AL USA (pc.)") -> AL USA (pc.) | J17: =IFERROR(__xludf.DUMMYFUNCTION("""COMPUTED_VALUE"""),0.107) -> 0.107 | K17: =IFERROR(__xludf.DUMMYFUNCTION("""COMPUTED_VALUE"""),0.18189999999999998) -> 0.1819 | L17: =IFERROR(__xludf.DUMMYFUNCTION("""COMPUTED_VALUE"""),"AL cast USA (pc.)") -> AL cast USA (pc.) | M17: =IFERROR(__xludf.DUMMYFUNCTION("""COMPUTED_VALUE"""),0.127) -> 0.127 | N17: =IFERROR(__xludf.DUMMYFUNCTION("""COMPUTED_VALUE"""),"")
A18: =IFERROR(__xludf.DUMMYFUNCTION("""COMPUTED_VALUE"""),"575-91004") -> 575-91004 | B18: =IFERROR(__xludf.DUMMYFUNCTION("""COMPUTED_VALUE"""),"DC25FS14 </= 9 min. 3/8"" shaft flange side con") -> DC25FS14 </= 9 min. 3/8" shaft flange side con | C18: =IFERROR(__xludf.DUMMYFUNCTION("""COMPUTED_VALUE"""),1.18148) -> 1.18148 | D18: =IFERROR(__xludf.DUMMYFUNCTION("""COMPUTED_VALUE"""),1.18148) -> 1.18148 | E18: =IFERROR(__xludf.DUMMYFUNCTION("""COMPUTED_VALUE"""),"") | F18: =IFERROR(__xludf.DUMMYFUNCTION("""COMPUTED_VALUE"""),"Cast AL Bulgaria (pc.)") -> Cast AL Bulgaria (pc.) | G18: =IFERROR(__xludf.DUMMYFUNCTION("""COMPUTED_VALUE"""),0.228) -> 0.228 | H18: =IFERROR(__xludf.DUMMYFUNCTION("""COMPUTED_VALUE"""),1.06248) -> 1.06248 | I18: =IFERROR(__xludf.DUMMYFUNCTION("""COMPUTED_VALUE"""),"AL USA (pc.)") -> AL USA (pc.) | J18: =IFERROR(__xludf.DUMMYFUNCTION("""COMPUTED_VALUE"""),0.07) -> 0.07 | K18: =IFERROR(__xludf.DUMMYFUNCTION("""COMPUTED_VALUE"""),0.11900000000000001) -> 0.119 | L18: =IFERROR(__xludf.DUMMYFUNCTION("""COMPUTED_VALUE"""),"") | M18: =IFERROR(__xludf.DUMMYFUNCTION("""COMPUTED_VALUE"""),"") | N18: =IFERROR(__xludf.DUMMYFUNCTION("""COMPUTED_VALUE"""),"")
A19: =IFERROR(__xludf.DUMMYFUNCTION("""COMPUTED_VALUE"""),"575-92002") -> 575-92002 | B19: =IFERROR(__xludf.DUMMYFUNCTION("""COMPUTED_VALUE"""),"DC25FE multiturn body 3/8"" shaft flange") -> DC25FE multiturn body 3/8" shaft flange | C19: =IFERROR(__xludf.DUMMYFUNCTION("""COMPUTED_VALUE"""),3.2294000000000005) -> 3.2294 | D19: =IFERROR(__xludf.DUMMYFUNCTION("""COMPUTED_VALUE"""),3.2294000000000005) -> 3.2294 | E19: =IFERROR(__xludf.DUMMYFUNCTION("""COMPUTED_VALUE"""),"") | F19: =IFERROR(__xludf.DUMMYFUNCTION("""COMPUTED_VALUE"""),"Ф65 AL 2017 Italy") -> Ф65 AL 2017 Italy | G19: =IFERROR(__xludf.DUMMYFUNCTION("""COMPUTED_VALUE"""),0.24) -> 0.24 | H19: =IFERROR(__xludf.DUMMYFUNCTION("""COMPUTED_VALUE"""),3.1104000000000003) -> 3.1104 | I19: =IFERROR(__xludf.DUMMYFUNCTION("""COMPUTED_VALUE"""),"AL USA (pc.)") -> AL USA (pc.) | J19: =IFERROR(__xludf.DUMMYFUNCTION("""COMPUTED_VALUE"""),0.07) -> 0.07 | K19: =IFERROR(__xludf.DUMMYFUNCTION("""COMPUTED_VALUE"""),0.11900000000000001) -> 0.119 | L19: =IFERROR(__xludf.DUMMYFUNCTION("""COMPUTED_VALUE"""),"") | M19: =IFERROR(__xludf.DUMMYFUNCTION("""COMPUTED_VALUE"""),"") | N19: =IFERROR(__xludf.DUMMYFUNCTION("""COMPUTED_VALUE"""),"")
A20: =IFERROR(__xludf.DUMMYFUNCTION("""COMPUTED_VALUE"""),"DC25-4FS(16)") -> DC25-4FS(16) | B20: =IFERROR(__xludf.DUMMYFUNCTION("""COMPUTED_VALUE"""),"DC25 housing 4 Speed Side Conn. 3/8"" shaft ") -> DC25 housing 4 Speed Side Conn. 3/8" shaft | C20: =IFERROR(__xludf.DUMMYFUNCTION("""COMPUTED_VALUE"""),1.15352) -> 1.15352 | D20: =IFERROR(__xludf.DUMMYFUNCTION("""COMPUTED_VALUE"""),1.15352) -> 1.15352 | E20: =IFERROR(__xludf.DUMMYFUNCTION("""COMPUTED_VALUE"""),"") | F20: =IFERROR(__xludf.DUMMYFUNCTION("""COMPUTED_VALUE"""),"Cast AL Bulgaria (pc.)") -> Cast AL Bulgaria (pc.) | G20: =IFERROR(__xludf.DUMMYFUNCTION("""COMPUTED_VALUE"""),0.222) -> 0.222 | H20: =IFERROR(__xludf.DUMMYFUNCTION("""COMPUTED_VALUE"""),1.03452) -> 1.03452 | I20: =IFERROR(__xludf.DUMMYFUNCTION("""COMPUTED_VALUE"""),"AL USA (pc.)") -> AL USA (pc.) | J20: =IFERROR(__xludf.DUMMYFUNCTION("""COMPUTED_VALUE"""),0.07) -> 0.07 | K20: =IFERROR(__xludf.DUMMYFUNCTION("""COMPUTED_VALUE"""),0.11900000000000001) -> 0.119 | L20: =IFERROR(__xludf.DUMMYFUNCTION("""COMPUTED_VALUE"""),"") | M20: =IFERROR(__xludf.DUMMYFUNCTION("""COMPUTED_VALUE"""),"") | N20: =IFERROR(__xludf.DUMMYFUNCTION("""COMPUTED_VALUE"""),"")
A21: =IFERROR(__xludf.DUMMYFUNCTION("""COMPUTED_VALUE"""),"H25-FS") -> H25-FS | B21: =IFERROR(__xludf.DUMMYFUNCTION("""COMPUTED_VALUE"""),"Size 25 resolver 3/8 shaft Flange mount side connector 0.95 TR @5000Hz") -> Size 25 resolver 3/8 shaft Flange mount side connector 0.95 TR @5000Hz | C21: =IFERROR(__xludf.DUMMYFUNCTION("""COMPUTED_VALUE"""),1.8503) -> 1.8503 | D21: =IFERROR(__xludf.DUMMYFUNCTION("""COMPUTED_VALUE"""),1.8503) -> 1.8503 | E21: =IFERROR(__xludf.DUMMYFUNCTION("""COMPUTED_VALUE"""),"") | F21: =IFERROR(__xludf.DUMMYFUNCTION("""COMPUTED_VALUE"""),"Cast AL Bulgaria (pc.)") -> Cast AL Bulgaria (pc.) | G21: =IFERROR(__xludf.DUMMYFUNCTION("""COMPUTED_VALUE"""),0.213) -> 0.213 | H21: =IFERROR(__xludf.DUMMYFUNCTION("""COMPUTED_VALUE"""),0.99258) -> 0.99258 | I21: =IFERROR(__xludf.DUMMYFUNCTION("""COMPUTED_VALUE"""),"AL USA (pc.)") -> AL USA (pc.) | J21: =IFERROR(__xludf.DUMMYFUNCTION("""COMPUTED_VALUE"""),0.07) -> 0.07 | K21: =IFERROR(__xludf.DUMMYFUNCTION("""COMPUTED_VALUE"""),0.11900000000000001) -> 0.119 | L21: =IFERROR(__xludf.DUMMYFUNCTION("""COMPUTED_VALUE"""),"Ф65 AL 2017 Italy") -> Ф65 AL 2017 Italy | M21: =IFERROR(__xludf.DUMMYFUNCTION("""COMPUTED_VALUE"""),0.057) -> 0.057 | N21: =IFERROR(__xludf.DUMMYFUNCTION("""COMPUTED_VALUE"""),0.73872) -> 0.73872
A22: =IFERROR(__xludf.DUMMYFUNCTION("""COMPUTED_VALUE"""),"575-93002") -> 575-93002 | B22: =IFERROR(__xludf.DUMMYFUNCTION("""COMPUTED_VALUE"""),"H25 Resolver 5/8"" shaft MS-16 end conn. w/o seal Short body") -> H25 Resolver 5/8" shaft MS-16 end conn. w/o seal Short body | C22: =IFERROR(__xludf.DUMMYFUNCTION("""COMPUTED_VALUE"""),4.3620600000000005) -> 4.36206 | D22: =IFERROR(__xludf.DUMMYFUNCTION("""COMPUTED_VALUE"""),4.3620600000000005) -> 4.36206 | E22: =IFERROR(__xludf.DUMMYFUNCTION("""COMPUTED_VALUE"""),"") | F22: =IFERROR(__xludf.DUMMYFUNCTION("""COMPUTED_VALUE"""),"Ф65 AL 2017 Italy") -> Ф65 AL 2017 Italy | G22: =IFERROR(__xludf.DUMMYFUNCTION("""COMPUTED_VALUE"""),0.311) -> 0.311 | H22: =IFERROR(__xludf.DUMMYFUNCTION("""COMPUTED_VALUE"""),4.03056) -> 4.03056 | I22: =IFERROR(__xludf.DUMMYFUNCTION("""COMPUTED_VALUE"""),"AL USA") -> AL USA | J22: =IFERROR(__xludf.DUMMYFUNCTION("""COMPUTED_VALUE"""),0.195) -> 0.195 | K22: =IFERROR(__xludf.DUMMYFUNCTION("""COMPUTED_VALUE"""),0.3315) -> 0.3315 | L22: =IFERROR(__xludf.DUMMYFUNCTION("""COMPUTED_VALUE"""),"") | M22: =IFERROR(__xludf.DUMMYFUNCTION("""COMPUTED_VALUE"""),"") | N22: =IFERROR(__xludf.DUMMYFUNCTION("""COMPUTED_VALUE"""),"")
A23: =IFERROR(__xludf.DUMMYFUNCTION("""COMPUTED_VALUE"""),"575-92011") -> 575-92011 | B23: =IFERROR(__xludf.DUMMYFUNCTION("""COMPUTED_VALUE"""),"DC 25FS Singleturn body 5/8"" shaft flange SSI Dura MS23 side conn </= 9min") -> DC 25FS Singleturn body 5/8" shaft flange SSI Dura MS23 side conn </= 9min | C23: =IFERROR(__xludf.DUMMYFUNCTION("""COMPUTED_VALUE"""),1.4219400000000002) -> 1.42194 | D23: =IFERROR(__xludf.DUMMYFUNCTION("""COMPUTED_VALUE"""),1.4219400000000002) -> 1.42194 | E23: =IFERROR(__xludf.DUMMYFUNCTION("""COMPUTED_VALUE"""),"") | F23: =IFERROR(__xludf.DUMMYFUNCTION("""COMPUTED_VALUE"""),"Cast AL Bulgaria (pc.)") -> Cast AL Bulgaria (pc.) | G23: =IFERROR(__xludf.DUMMYFUNCTION("""COMPUTED_VALUE"""),0.234) -> 0.234 | H23: =IFERROR(__xludf.DUMMYFUNCTION("""COMPUTED_VALUE"""),1.09044) -> 1.09044 | I23: =IFERROR(__xludf.DUMMYFUNCTION("""COMPUTED_VALUE"""),"AL USA") -> AL USA | J23: =IFERROR(__xludf.DUMMYFUNCTION("""COMPUTED_VALUE"""),0.195) -> 0.195 | K23: =IFERROR(__xludf.DUMMYFUNCTION("""COMPUTED_VALUE"""),0.3315) -> 0.3315 | L23: =IFERROR(__xludf.DUMMYFUNCTION("""COMPUTED_VALUE"""),"") | M23: =IFERROR(__xludf.DUMMYFUNCTION("""COMPUTED_VALUE"""),"") | N23: =IFERROR(__xludf.DUMMYFUNCTION("""COMPUTED_VALUE"""),"")
A24: =IFERROR(__xludf.DUMMYFUNCTION("""COMPUTED_VALUE"""),"575-91055") -> 575-91055 | B24: =IFERROR(__xludf.DUMMYFUNCTION("""COMPUTED_VALUE"""),"H25-w/ Special servo nose Two flats on shaft TR=0.95 @ 5KHz") -> H25-w/ Special servo nose Two flats on shaft TR=0.95 @ 5KHz | C24: =IFERROR(__xludf.DUMMYFUNCTION("""COMPUTED_VALUE"""),2.7914000000000003) -> 2.7914 | D24: =IFERROR(__xludf.DUMMYFUNCTION("""COMPUTED_VALUE"""),2.7914000000000003) -> 2.7914 | E24: =IFERROR(__xludf.DUMMYFUNCTION("""COMPUTED_VALUE"""),"") | F24: =IFERROR(__xludf.DUMMYFUNCTION("""COMPUTED_VALUE"""),"Cast AL Bulgaria (pc.)") -> Cast AL Bulgaria (pc.) | G24: =IFERROR(__xludf.DUMMYFUNCTION("""COMPUTED_VALUE"""),0.218) -> 0.218 | H24: =IFERROR(__xludf.DUMMYFUNCTION("""COMPUTED_VALUE"""),1.0158800000000001) -> 1.01588 | I24: =IFERROR(__xludf.DUMMYFUNCTION("""COMPUTED_VALUE"""),"Ф65 AL 2017 Italy") -> Ф65 AL 2017 Italy | J24: =IFERROR(__xludf.DUMMYFUNCTION("""COMPUTED_VALUE"""),0.08) -> 0.08 | K24: =IFERROR(__xludf.DUMMYFUNCTION("""COMPUTED_VALUE"""),1.0368000000000002) -> 1.0368 | L24: =IFERROR(__xludf.DUMMYFUNCTION("""COMPUTED_VALUE"""),"Ф65 AL 2017 Italy") -> Ф65 AL 2017 Italy | M24: =IFERROR(__xludf.DUMMYFUNCTION("""COMPUTED_VALUE"""),0.057) -> 0.057 | N24: =IFERROR(__xludf.DUMMYFUNCTION("""COMPUTED_VALUE"""),0.73872) -> 0.73872
A25: =IFERROR(__xludf.DUMMYFUNCTION("""COMPUTED_VALUE"""),"575-91009") -> 575-91009 | B25: =IFERROR(__xludf.DUMMYFUNCTION("""COMPUTED_VALUE"""),"DC25FS18 </= 9 min 3/8"" shaft flange side conn") -> DC25FS18 </= 9 min 3/8" shaft flange side conn | C25: =IFERROR(__xludf.DUMMYFUNCTION("""COMPUTED_VALUE"""),1.13488) -> 1.13488 | D25: =IFERROR(__xludf.DUMMYFUNCTION("""COMPUTED_VALUE"""),1.13488) -> 1.13488 | E25: =IFERROR(__xludf.DUMMYFUNCTION("""COMPUTED_VALUE"""),"") | F25: =IFERROR(__xludf.DUMMYFUNCTION("""COMPUTED_VALUE"""),"Cast AL Bulgaria (pc.)") -> Cast AL Bulgaria (pc.) | G25: =IFERROR(__xludf.DUMMYFUNCTION("""COMPUTED_VALUE"""),0.218) -> 0.218 | H25: =IFERROR(__xludf.DUMMYFUNCTION("""COMPUTED_VALUE"""),1.0158800000000001) -> 1.01588 | I25: =IFERROR(__xludf.DUMMYFUNCTION("""COMPUTED_VALUE"""),"AL USA (pc.)") -> AL USA (pc.) | J25: =IFERROR(__xludf.DUMMYFUNCTION("""COMPUTED_VALUE"""),0.07) -> 0.07 | K25: =IFERROR(__xludf.DUMMYFUNCTION("""COMPUTED_VALUE"""),0.11900000000000001) -> 0.119 | L25: =IFERROR(__xludf.DUMMYFUNCTION("""COMPUTED_VALUE"""),"") | M25: =IFERROR(__xludf.DUMMYFUNCTION("""COMPUTED_VALUE"""),"") | N25: =IFERROR(__xludf.DUMMYFUNCTION("""COMPUTED_VALUE"""),"")
A26: =IFERROR(__xludf.DUMMYFUNCTION("""COMPUTED_VALUE"""),"22140702A") -> 22140702A | B26: =IFERROR(__xludf.DUMMYFUNCTION("""COMPUTED_VALUE"""),"H25 Body with Shaft zeroed for HT-400x-j Single turn TR=0.95, 5KHz, w/o conn") -> H25 Body with Shaft zeroed for HT-400x-j Single turn TR=0.95, 5KHz, w/o conn | C26: =IFERROR(__xludf.DUMMYFUNCTION("""COMPUTED_VALUE"""),4.03056) -> 4.03056 | D26: =IFERROR(__xludf.DUMMYFUNCTION("""COMPUTED_VALUE"""),4.03056) -> 4.03056 | E26: =IFERROR(__xludf.DUMMYFUNCTION("""COMPUTED_VALUE"""),"") | F26: =IFERROR(__xludf.DUMMYFUNCTION("""COMPUTED_VALUE"""),"Ф65 AL 2017 Italy") -> Ф65 AL 2017 Italy | G26: =IFERROR(__xludf.DUMMYFUNCTION("""COMPUTED_VALUE"""),0.311) -> 0.311 | H26: =IFERROR(__xludf.DUMMYFUNCTION("""COMPUTED_VALUE"""),4.03056) -> 4.03056 | I26: =IFERROR(__xludf.DUMMYFUNCTION("""COMPUTED_VALUE"""),"") | J26: =IFERROR(__xludf.DUMMYFUNCTION("""COMPUTED_VALUE"""),"") | K26: =IFERROR(__xludf.DUMMYFUNCTION("""COMPUTED_VALUE"""),"") | L26: =IFERROR(__xludf.DUMMYFUNCTION("""COMPUTED_VALUE"""),"") | M26: =IFERROR(__xludf.DUMMYFUNCTION("""COMPUTED_VALUE"""),"") | N26: =IFERROR(__xludf.DUMMYFUNCTION("""COMPUTED_VALUE"""),"")
A27: =IFERROR(__xludf.DUMMYFUNCTION("""COMPUTED_VALUE"""),"575-92003") -> 575-92003 | B27: =IFERROR(__xludf.DUMMYFUNCTION("""COMPUTED_VALUE"""),"DC25FS, Singleturn Body 3/8"" shaft, Flange SSI Durac MS23 side conn.") -> DC25FS, Singleturn Body 3/8" shaft, Flange SSI Durac MS23 side conn. | C27: =IFERROR(__xludf.DUMMYFUNCTION("""COMPUTED_VALUE"""),1.20944) -> 1.20944 | D27: =IFERROR(__xludf.DUMMYFUNCTION("""COMPUTED_VALUE"""),1.20944) -> 1.20944 | E27: =IFERROR(__xludf.DUMMYFUNCTION("""COMPUTED_VALUE"""),"") | F27: =IFERROR(__xludf.DUMMYFUNCTION("""COMPUTED_VALUE"""),"Cast AL Bulgaria (pc.)") -> Cast AL Bulgaria (pc.) | G27: =IFERROR(__xludf.DUMMYFUNCTION("""COMPUTED_VALUE"""),0.234) -> 0.234 | H27: =IFERROR(__xludf.DUMMYFUNCTION("""COMPUTED_VALUE"""),1.09044) -> 1.09044 | I27: =IFERROR(__xludf.DUMMYFUNCTION("""COMPUTED_VALUE"""),"AL USA (pc.)") -> AL USA (pc.) | J27: =IFERROR(__xludf.DUMMYFUNCTION("""COMPUTED_VALUE"""),0.07) -> 0.07 | K27: =IFERROR(__xludf.DUMMYFUNCTION("""COMPUTED_VALUE"""),0.11900000000000001) -> 0.119 | L27: =IFERROR(__xludf.DUMMYFUNCTION("""COMPUTED_VALUE"""),"") | M27: =IFERROR(__xludf.DUMMYFUNCTION("""COMPUTED_VALUE"""),"") | N27: =IFERROR(__xludf.DUMMYFUNCTION("""COMPUTED_VALUE"""),"")
A28: =IFERROR(__xludf.DUMMYFUNCTION("""COMPUTED_VALUE"""),"H25-FS-R3N") -> H25-FS-R3N | B28: =IFERROR(__xludf.DUMMYFUNCTION("""COMPUTED_VALUE"""),"Size 25 resolver 3/8"" shaft side mount w/ 10 pin conn") -> Size 25 resolver 3/8" shaft side mount w/ 10 pin conn | C28: =IFERROR(__xludf.DUMMYFUNCTION("""COMPUTED_VALUE"""),1.77574) -> 1.77574 | D28: =IFERROR(__xludf.DUMMYFUNCTION("""COMPUTED_VALUE"""),1.77574) -> 1.77574 | E28: =IFERROR(__xludf.DUMMYFUNCTION("""COMPUTED_VALUE"""),"") | F28: =IFERROR(__xludf.DUMMYFUNCTION("""COMPUTED_VALUE"""),"Cast AL Bulgaria (pc.)") -> Cast AL Bulgaria (pc.) | G28: =IFERROR(__xludf.DUMMYFUNCTION("""COMPUTED_VALUE"""),0.197) -> 0.197 | H28: =IFERROR(__xludf.DUMMYFUNCTION("""COMPUTED_VALUE"""),0.9180200000000001) -> 0.91802 | I28: =IFERROR(__xludf.DUMMYFUNCTION("""COMPUTED_VALUE"""),"AL USA (pc.)") -> AL USA (pc.) | J28: =IFERROR(__xludf.DUMMYFUNCTION("""COMPUTED_VALUE"""),0.07) -> 0.07 | K28: =IFERROR(__xludf.DUMMYFUNCTION("""COMPUTED_VALUE"""),0.11900000000000001) -> 0.119 | L28: =IFERROR(__xludf.DUMMYFUNCTION("""COMPUTED_VALUE"""),"Ф65 AL 2017 Italy") -> Ф65 AL 2017 Italy | M28: =IFERROR(__xludf.DUMMYFUNCTION("""COMPUTED_VALUE"""),0.057) -> 0.057 | N28: =IFERROR(__xludf.DUMMYFUNCTION("""COMPUTED_VALUE"""),0.73872) -> 0.73872
A29: =IFERROR(__xludf.DUMMYFUNCTION("""COMPUTED_VALUE"""),"H25-SE-10") -> H25-SE-10 | B29: =IFERROR(__xludf.DUMMYFUNCTION("""COMPUTED_VALUE"""),"Transducer 1 Turn C&A Flange servo mount with 10mm shaft") -> Transducer 1 Turn C&A Flange servo mount with 10mm shaft | C29: =IFERROR(__xludf.DUMMYFUNCTION("""COMPUTED_VALUE"""),4.717440000000001) -> 4.71744 | D29: =IFERROR(__xludf.DUMMYFUNCTION("""COMPUTED_VALUE"""),4.717440000000001) -> 4.71744 | E29: =IFERROR(__xludf.DUMMYFUNCTION("""COMPUTED_VALUE"""),"") | F29: =IFERROR(__xludf.DUMMYFUNCTION("""COMPUTED_VALUE"""),"Ф65 AL 2017 Italy") -> Ф65 AL 2017 Italy | G29: =IFERROR(__xludf.DUMMYFUNCTION("""COMPUTED_VALUE"""),0.311) -> 0.311 | H29: =IFERROR(__xludf.DUMMYFUNCTION("""COMPUTED_VALUE"""),4.03056) -> 4.03056 | I29: =IFERROR(__xludf.DUMMYFUNCTION("""COMPUTED_VALUE"""),"Ф65 AL 2017 Italy") -> Ф65 AL 2017 Italy | J29: =IFERROR(__xludf.DUMMYFUNCTION("""COMPUTED_VALUE"""),0.053) -> 0.053 | K29: =IFERROR(__xludf.DUMMYFUNCTION("""COMPUTED_VALUE"""),0.68688) -> 0.68688 | L29: =IFERROR(__xludf.DUMMYFUNCTION("""COMPUTED_VALUE"""),"") | M29: =IFERROR(__xludf.DUMMYFUNCTION("""COMPUTED_VALUE"""),"") | N29: =IFERROR(__xludf.DUMMYFUNCTION("""COMPUTED_VALUE"""),"")
A30: =IFERROR(__xludf.DUMMYFUNCTION("""COMPUTED_VALUE"""),"22140701А") -> 22140701А | B30: =IFERROR(__xludf.DUMMYFUNCTION("""COMPUTED_VALUE"""),"H25 Body with Shaft zeroed for HT-400x-L Single turn TR=1,4, 5KHz,2250Hz w/o conn") -> H25 Body with Shaft zeroed for HT-400x-L Single turn TR=1,4, 5KHz,2250Hz w/o conn | C30: =IFERROR(__xludf.DUMMYFUNCTION("""COMPUTED_VALUE"""),4.03056) -> 4.03056 | D30: =IFERROR(__xludf.DUMMYFUNCTION("""COMPUTED_VALUE"""),4.03056) -> 4.03056 | E30: =IFERROR(__xludf.DUMMYFUNCTION("""COMPUTED_VALUE"""),"") | F30: =IFERROR(__xludf.DUMMYFUNCTION("""COMPUTED_VALUE"""),"Ф65 AL 2017 Italy") -> Ф65 AL 2017 Italy | G30: =IFERROR(__xludf.DUMMYFUNCTION("""COMPUTED_VALUE"""),0.311) -> 0.311 | H30: =IFERROR(__xludf.DUMMYFUNCTION("""COMPUTED_VALUE"""),4.03056) -> 4.03056 | I30: =IFERROR(__xludf.DUMMYFUNCTION("""COMPUTED_VALUE"""),"") | J30: =IFERROR(__xludf.DUMMYFUNCTION("""COMPUTED_VALUE"""),"") | K30: =IFERROR(__xludf.DUMMYFUNCTION("""COMPUTED_VALUE"""),"") | L30: =IFERROR(__xludf.DUMMYFUNCTION("""COMPUTED_VALUE"""),"") | M30: =IFERROR(__xludf.DUMMYFUNCTION("""COMPUTED_VALUE"""),"") | N30: =IFERROR(__xludf.DUMMYFUNCTION("""COMPUTED_VALUE"""),"")
A31: =IFERROR(__xludf.DUMMYFUNCTION("""COMPUTED_VALUE"""),"575-91007") -> 575-91007 | B31: =IFERROR(__xludf.DUMMYFUNCTION("""COMPUTED_VALUE"""),"DC25FS16 </=9 min. 3/8"" shaft, flange , side conn") -> DC25FS16 </=9 min. 3/8" shaft, flange , side conn | C31: =IFERROR(__xludf.DUMMYFUNCTION("""COMPUTED_VALUE"""),1.15352) -> 1.15352 | D31: =IFERROR(__xludf.DUMMYFUNCTION("""COMPUTED_VALUE"""),1.15352) -> 1.15352 | E31: =IFERROR(__xludf.DUMMYFUNCTION("""COMPUTED_VALUE"""),"") | F31: =IFERROR(__xludf.DUMMYFUNCTION("""COMPUTED_VALUE"""),"Cast AL Bulgaria (pc.)") -> Cast AL Bulgaria (pc.) | G31: =IFERROR(__xludf.DUMMYFUNCTION("""COMPUTED_VALUE"""),0.222) -> 0.222 | H31: =IFERROR(__xludf.DUMMYFUNCTION("""COMPUTED_VALUE"""),1.03452) -> 1.03452 | I31: =IFERROR(__xludf.DUMMYFUNCTION("""COMPUTED_VALUE"""),"AL USA (pc.)") -> AL USA (pc.) | J31: =IFERROR(__xludf.DUMMYFUNCTION("""COMPUTED_VALUE"""),0.07) -> 0.07 | K31: =IFERROR(__xludf.DUMMYFUNCTION("""COMPUTED_VALUE"""),0.11900000000000001) -> 0.119 | L31: =IFERROR(__xludf.DUMMYFUNCTION("""COMPUTED_VALUE"""),"") | M31: =IFERROR(__xludf.DUMMYFUNCTION("""COMPUTED_VALUE"""),"") | N31: =IFERROR(__xludf.DUMMYFUNCTION("""COMPUTED_VALUE"""),"")
A32: =IFERROR(__xludf.DUMMYFUNCTION("""COMPUTED_VALUE"""),"H25-FE-10") -> H25-FE-10 | B32: =IFERROR(__xludf.DUMMYFUNCTION("""COMPUTED_VALUE"""),"Transducer 1 Turn C&A Flange TR=0.95, 5KHz, w/o conn") -> Transducer 1 Turn C&A Flange TR=0.95, 5KHz, w/o conn | C32: =IFERROR(__xludf.DUMMYFUNCTION("""COMPUTED_VALUE"""),4.14956) -> 4.14956 | D32: =IFERROR(__xludf.DUMMYFUNCTION("""COMPUTED_VALUE"""),4.14956) -> 4.14956 | E32: =IFERROR(__xludf.DUMMYFUNCTION("""COMPUTED_VALUE"""),"") | F32: =IFERROR(__xludf.DUMMYFUNCTION("""COMPUTED_VALUE"""),"Ф65 AL 2017 Italy") -> Ф65 AL 2017 Italy | G32: =IFERROR(__xludf.DUMMYFUNCTION("""COMPUTED_VALUE"""),0.311) -> 0.311 | H32: =IFERROR(__xludf.DUMMYFUNCTION("""COMPUTED_VALUE"""),4.03056) -> 4.03056 | I32: =IFERROR(__xludf.DUMMYFUNCTION("""COMPUTED_VALUE"""),"AL USA (pc.)") -> AL USA (pc.) | J32: =IFERROR(__xludf.DUMMYFUNCTION("""COMPUTED_VALUE"""),0.07) -> 0.07 | K32: =IFERROR(__xludf.DUMMYFUNCTION("""COMPUTED_VALUE"""),0.11900000000000001) -> 0.119 | L32: =IFERROR(__xludf.DUMMYFUNCTION("""COMPUTED_VALUE"""),"") | M32: =IFERROR(__xludf.DUMMYFUNCTION("""COMPUTED_VALUE"""),"") | N32: =IFERROR(__xludf.DUMMYFUNCTION("""COMPUTED_VALUE"""),"")
A33: =IFERROR(__xludf.DUMMYFUNCTION("""COMPUTED_VALUE"""),"H25-SS") -> H25-SS | B33: =IFERROR(__xludf.DUMMYFUNCTION("""COMPUTED_VALUE"""),"Size 25 resolver servo with side connector 0.95 TR@5000Hz 3/8"" shaft") -> Size 25 resolver servo with side connector 0.95 TR@5000Hz 3/8" shaft | C33: =IFERROR(__xludf.DUMMYFUNCTION("""COMPUTED_VALUE"""),2.4181800000000004) -> 2.41818 | D33: =IFERROR(__xludf.DUMMYFUNCTION("""COMPUTED_VALUE"""),2.4181800000000004) -> 2.41818 | E33: =IFERROR(__xludf.DUMMYFUNCTION("""COMPUTED_VALUE"""),"") | F33: =IFERROR(__xludf.DUMMYFUNCTION("""COMPUTED_VALUE"""),"Cast AL Bulgaria (pc.)") -> Cast AL Bulgaria (pc.) | G33: =IFERROR(__xludf.DUMMYFUNCTION("""COMPUTED_VALUE"""),0.213) -> 0.213 | H33: =IFERROR(__xludf.DUMMYFUNCTION("""COMPUTED_VALUE"""),0.99258) -> 0.99258 | I33: =IFERROR(__xludf.DUMMYFUNCTION("""COMPUTED_VALUE"""),"Ф65 AL 2017 Italy") -> Ф65 AL 2017 Italy | J33: =IFERROR(__xludf.DUMMYFUNCTION("""COMPUTED_VALUE"""),0.053) -> 0.053 | K33: =IFERROR(__xludf.DUMMYFUNCTION("""COMPUTED_VALUE"""),0.68688) -> 0.68688 | L33: =IFERROR(__xludf.DUMMYFUNCTION("""COMPUTED_VALUE"""),"Ф65 AL 2017 Italy") -> Ф65 AL 2017 Italy | M33: =IFERROR(__xludf.DUMMYFUNCTION("""COMPUTED_VALUE"""),0.057) -> 0.057 | N33: =IFERROR(__xludf.DUMMYFUNCTION("""COMPUTED_VALUE"""),0.73872) -> 0.73872
A34: =IFERROR(__xludf.DUMMYFUNCTION("""COMPUTED_VALUE"""),"575-01921") -> 575-01921 | B34: =IFERROR(__xludf.DUMMYFUNCTION("""COMPUTED_VALUE"""),"Resolver size 11, TR=0.5 2500 Hz, Control Transmitter +/- 7min.; 0,12"" shaft") -> Resolver size 11, TR=0.5 2500 Hz, Control Transmitter +/- 7min.; 0,12" shaft | C34: =IFERROR(__xludf.DUMMYFUNCTION("""COMPUTED_VALUE"""),0.0) -> 0 | D34: =IFERROR(__xludf.DUMMYFUNCTION("""COMPUTED_VALUE"""),"") | E34: =IFERROR(__xludf.DUMMYFUNCTION("""COMPUTED_VALUE"""),"") | G34: =IFERROR(__xludf.DUMMYFUNCTION("""COMPUTED_VALUE"""),"") | H34: =IFERROR(__xludf.DUMMYFUNCTION("""COMPUTED_VALUE"""),"") | I34: =IFERROR(__xludf.DUMMYFUNCTION("""COMPUTED_VALUE"""),"") | J34: =IFERROR(__xludf.DUMMYFUNCTION("""COMPUTED_VALUE"""),"") | K34: =IFERROR(__xludf.DUMMYFUNCTION("""COMPUTED_VALUE"""),"") | L34: =IFERROR(__xludf.DUMMYFUNCTION("""COMPUTED_VALUE"""),"") | M34: =IFERROR(__xludf.DUMMYFUNCTION("""COMPUTED_VALUE"""),"") | N34: =IFERROR(__xludf.DUMMYFUNCTION("""COMPUTED_VALUE"""),"")
A35: =IFERROR(__xludf.DUMMYFUNCTION("""COMPUTED_VALUE"""),"575-01912-3") -> 575-01912-3 | B35: =IFERROR(__xludf.DUMMYFUNCTION("""COMPUTED_VALUE"""),"Resolver size 11, TR=0,45 1000Hz, Acc. 3min. Transmitter; 0,12"" shaft with flat") -> Resolver size 11, TR=0,45 1000Hz, Acc. 3min. Transmitter; 0,12" shaft with flat | C35: =IFERROR(__xludf.DUMMYFUNCTION("""COMPUTED_VALUE"""),0.0) -> 0 | D35: =IFERROR(__xludf.DUMMYFUNCTION("""COMPUTED_VALUE"""),"") | E35: =IFERROR(__xludf.DUMMYFUNCTION("""COMPUTED_VALUE"""),"") | G35: =IFERROR(__xludf.DUMMYFUNCTION("""COMPUTED_VALUE"""),"") | H35: =IFERROR(__xludf.DUMMYFUNCTION("""COMPUTED_VALUE"""),"") | I35: =IFERROR(__xludf.DUMMYFUNCTION("""COMPUTED_VALUE"""),"") | J35: =IFERROR(__xludf.DUMMYFUNCTION("""COMPUTED_VALUE"""),"") | K35: =IFERROR(__xludf.DUMMYFUNCTION("""COMPUTED_VALUE"""),"") | L35: =IFERROR(__xludf.DUMMYFUNCTION("""COMPUTED_VALUE"""),"") | M35: =IFERROR(__xludf.DUMMYFUNCTION("""COMPUTED_VALUE"""),"") | N35: =IFERROR(__xludf.DUMMYFUNCTION("""COMPUTED_VALUE"""),"")
A36: =IFERROR(__xludf.DUMMYFUNCTION("""COMPUTED_VALUE"""),"575-01902") -> 575-01902 | B36: =IFERROR(__xludf.DUMMYFUNCTION("""COMPUTED_VALUE"""),"Resolver size 11, TR-0,95 Transmitter 5KHz; sorted into -1,-4,-8,-10") -> Resolver size 11, TR-0,95 Transmitter 5KHz; sorted into -1,-4,-8,-10 | C36: =IFERROR(__xludf.DUMMYFUNCTION("""COMPUTED_VALUE"""),0.0) -> 0 | D36: =IFERROR(__xludf.DUMMYFUNCTION("""COMPUTED_VALUE"""),"") | E36: =IFERROR(__xludf.DUMMYFUNCTION("""COMPUTED_VALUE"""),"") | G36: =IFERROR(__xludf.DUMMYFUNCTION("""COMPUTED_VALUE"""),"") | H36: =IFERROR(__xludf.DUMMYFUNCTION("""COMPUTED_VALUE"""),"") | I36: =IFERROR(__xludf.DUMMYFUNCTION("""COMPUTED_VALUE"""),"") | J36: =IFERROR(__xludf.DUMMYFUNCTION("""COMPUTED_VALUE"""),"") | K36: =IFERROR(__xludf.DUMMYFUNCTION("""COMPUTED_VALUE"""),"") | L36: =IFERROR(__xludf.DUMMYFUNCTION("""COMPUTED_VALUE"""),"") | M36: =IFERROR(__xludf.DUMMYFUNCTION("""COMPUTED_VALUE"""),"") | N36: =IFERROR(__xludf.DUMMYFUNCTION("""COMPUTED_VALUE"""),"")
A37: =IFERROR(__xludf.DUMMYFUNCTION("""COMPUTED_VALUE"""),"575-01911-2") -> 575-01911-2 | B37: =IFERROR(__xludf.DUMMYFUNCTION("""COMPUTED_VALUE"""),"Resolver size 11, TR=,50 2500Hz ACCUR.=<7 with .30"" shaft lengt") -> Resolver size 11, TR=,50 2500Hz ACCUR.=<7 with .30" shaft lengt | C37: =IFERROR(__xludf.DUMMYFUNCTION("""COMPUTED_VALUE"""),0.0) -> 0 | D37: =IFERROR(__xludf.DUMMYFUNCTION("""COMPUTED_VALUE"""),"") | E37: =IFERROR(__xludf.DUMMYFUNCTION("""COMPUTED_VALUE"""),"") | G37: =IFERROR(__xludf.DUMMYFUNCTION("""COMPUTED_VALUE"""),"") | H37: =IFERROR(__xludf.DUMMYFUNCTION("""COMPUTED_VALUE"""),"") | I37: =IFERROR(__xludf.DUMMYFUNCTION("""COMPUTED_VALUE"""),"") | J37: =IFERROR(__xludf.DUMMYFUNCTION("""COMPUTED_VALUE"""),"") | K37: =IFERROR(__xludf.DUMMYFUNCTION("""COMPUTED_VALUE"""),"") | L37: =IFERROR(__xludf.DUMMYFUNCTION("""COMPUTED_VALUE"""),"") | M37: =IFERROR(__xludf.DUMMYFUNCTION("""COMPUTED_VALUE"""),"") | N37: =IFERROR(__xludf.DUMMYFUNCTION("""COMPUTED_VALUE"""),"")
A38: =IFERROR(__xludf.DUMMYFUNCTION("""COMPUTED_VALUE"""),"575-01912") -> 575-01912 | B38: =IFERROR(__xludf.DUMMYFUNCTION("""COMPUTED_VALUE"""),"Resolver size 11, TR=0,45 1000Hz, Transmitter Acc. Unsorted") -> Resolver size 11, TR=0,45 1000Hz, Transmitter Acc. Unsorted | C38: =IFERROR(__xludf.DUMMYFUNCTION("""COMPUTED_VALUE"""),0.0) -> 0 | D38: =IFERROR(__xludf.DUMMYFUNCTION("""COMPUTED_VALUE"""),"") | E38: =IFERROR(__xludf.DUMMYFUNCTION("""COMPUTED_VALUE"""),"") | G38: =IFERROR(__xludf.DUMMYFUNCTION("""COMPUTED_VALUE"""),"") | H38: =IFERROR(__xludf.DUMMYFUNCTION("""COMPUTED_VALUE"""),"") | I38: =IFERROR(__xludf.DUMMYFUNCTION("""COMPUTED_VALUE"""),"") | J38: =IFERROR(__xludf.DUMMYFUNCTION("""COMPUTED_VALUE"""),"") | K38: =IFERROR(__xludf.DUMMYFUNCTION("""COMPUTED_VALUE"""),"") | L38: =IFERROR(__xludf.DUMMYFUNCTION("""COMPUTED_VALUE"""),"") | M38: =IFERROR(__xludf.DUMMYFUNCTION("""COMPUTED_VALUE"""),"") | N38: =IFERROR(__xludf.DUMMYFUNCTION("""COMPUTED_VALUE"""),"")
A39: =IFERROR(__xludf.DUMMYFUNCTION("""COMPUTED_VALUE"""),"575-01924") -> 575-01924 | B39: =IFERROR(__xludf.DUMMYFUNCTION("""COMPUTED_VALUE"""),"Resolver size 11, TR=1,0 1000Hz, control Transmitter +/-7 min") -> Resolver size 11, TR=1,0 1000Hz, control Transmitter +/-7 min | C39: =IFERROR(__xludf.DUMMYFUNCTION("""COMPUTED_VALUE"""),0.0) -> 0 | D39: =IFERROR(__xludf.DUMMYFUNCTION("""COMPUTED_VALUE"""),"") | E39: =IFERROR(__xludf.DUMMYFUNCTION("""COMPUTED_VALUE"""),"") | G39: =IFERROR(__xludf.DUMMYFUNCTION("""COMPUTED_VALUE"""),"") | H39: =IFERROR(__xludf.DUMMYFUNCTION("""COMPUTED_VALUE"""),"") | I39: =IFERROR(__xludf.DUMMYFUNCTION("""COMPUTED_VALUE"""),"") | J39: =IFERROR(__xludf.DUMMYFUNCTION("""COMPUTED_VALUE"""),"") | K39: =IFERROR(__xludf.DUMMYFUNCTION("""COMPUTED_VALUE"""),"") | L39: =IFERROR(__xludf.DUMMYFUNCTION("""COMPUTED_VALUE"""),"") | M39: =IFERROR(__xludf.DUMMYFUNCTION("""COMPUTED_VALUE"""),"") | N39: =IFERROR(__xludf.DUMMYFUNCTION("""COMPUTED_VALUE"""),"")
A40: =IFERROR(__xludf.DUMMYFUNCTION("""COMPUTED_VALUE"""),"575-01920-1") -> 575-01920-1 | B40: =IFERROR(__xludf.DUMMYFUNCTION("""COMPUTED_VALUE"""),"Resolver size 11, TR=0.45 400Hz,Transmitter w/ flat; Acc.=<7 min.") -> Resolver size 11, TR=0.45 400Hz,Transmitter w/ flat; Acc.=<7 min. | C40: =IFERROR(__xludf.DUMMYFUNCTION("""COMPUTED_VALUE"""),0.0) -> 0 | D40: =IFERROR(__xludf.DUMMYFUNCTION("""COMPUTED_VALUE"""),"") | E40: =IFERROR(__xludf.DUMMYFUNCTION("""COMPUTED_VALUE"""),"") | G40: =IFERROR(__xludf.DUMMYFUNCTION("""COMPUTED_VALUE"""),"") | H40: =IFERROR(__xludf.DUMMYFUNCTION("""COMPUTED_VALUE"""),"") | I40: =IFERROR(__xludf.DUMMYFUNCTION("""COMPUTED_VALUE"""),"") | J40: =IFERROR(__xludf.DUMMYFUNCTION("""COMPUTED_VALUE"""),"") | K40: =IFERROR(__xludf.DUMMYFUNCTION("""COMPUTED_VALUE"""),"") | L40: =IFERROR(__xludf.DUMMYFUNCTION("""COMPUTED_VALUE"""),"") | M40: =IFERROR(__xludf.DUMMYFUNCTION("""COMPUTED_VALUE"""),"") | N40: =IFERROR(__xludf.DUMMYFUNCTION("""COMPUTED_VALUE"""),"")
...

Sheet Данни
A1: Номер | B1: Описание | C1: Unit cost | D1: HTS Code
A2: ='Номенклатура'!A2 | B2: ='Номенклатура'!B2
A3: ='Номенклатура'!A3 -> 575-60044 | B3: ='Номенклатура'!B3 -> DC60 Multiturn Body 3/8'' shaft; Nitrile seal Sq. Flange Side PG9 conn | C3: 113 | D3: 8543.90.8885
A4: ='Номенклатура'!A4 -> 575-91001-9 | B4: ='Номенклатура'!B4 -> DC25FS </= 9 min IP69Kw hole on shaft no knurl M12 side conn. HARSCO | C4: 91 | D4: 8543.90.8885
A5: ='Номенклатура'!A5 -> 575-92015 | B5: ='Номенклатура'!B5 -> DC25FE, Multiturn Body 5/8" shaft flange end conn. | C5: 91 | D5: 8543.90.8885
A6: ='Номенклатура'!A6 -> 575-93001 | B6: ='Номенклатура'!B6 -> H25 Resolver Shaft 5/8" With MS-16 side conn. w/o seal Short body | C6: 91 | D6: 8543.90.8885
A7: ='Номенклатура'!A7 -> H25-FE-06 | B7: ='Номенклатура'!B7 -> Transducer 1 Turn Flange Mntaligned at zero degrees With 3mm Key Way, 3/8"shaft | C7: 91 | D7: 8543.70.4500
A8: ='Номенклатура'!A8 -> H25-FE | B8: ='Номенклатура'!B8 -> Size 25 resolver 3/8" shaft Flange mount End connector 0.95 TR @ 5000 Hz | C8: 91 | D8: 8543.70.4500
A9: ='Номенклатура'!A9 -> 575-60007 | B9: ='Номенклатура'!B9 -> NR-60 Multi Body 10mm shaft Nitrile seal Square flange End conn. | C9: 113 | D9: 8543.90.8885
A10: ='Номенклатура'!A10 -> 575-91001 | B10: ='Номенклатура'!B10 -> DC25FE </= 9 min 3/8" sahft flange end conn. | C10: 91 | D10: 8543.90.8885
A11: ='Номенклатура'!A11 -> 575-92000 | B11: ='Номенклатура'!B11 -> DC25FS Multiturn Body 3/8" shaft Flange Multiturn Body 3/8" shaft MS23 side conn | C11: 91 | D11: 8543.70.4500
A12: ='Номенклатура'!A12 -> 575-92006 | B12: ='Номенклатура'!B12 -> DC25FE </= 9 min 5/8" shaft flange end conn | C12: 91 | D12: 8543.70.4500
A13: ='Номенклатура'!A13 -> DC25-2FE | B13: ='Номенклатура'!B13 -> DC25 Housing 2Sp. End conn. 3/8" shaft | D13: 8543.70.4500
A14: ='Номенклатура'!A14 -> H25-F1E | B14: ='Номенклатура'!B14 -> Transducer 1 Turn C&A Flange TR=0/95; 5KHz end conn. | C14: 91 | D14: 8543.70.4500
A15: ='Номенклатура'!A15 -> H25-FS-06 | B15: ='Номенклатура'!B15 -> Size 25 resolver 3/8" shaft Flange mount Side connector w/3 mm keyway | C15: 91 | D15: 8543.70.4500
A16: ='Номенклатура'!A16 -> H25-SE | B16: ='Номенклатура'!B16 -> Size 25 resolver 3/8" shaft servo mount End connector 0.95 0.95 T.R. @5000 Hz | C16: 91 | D16: 8543.70.4500
A17: ='Номенклатура'!A17 -> 575-60021 | B17: ='Номенклатура'!B17 -> NR-60 Encoder Avago assembly,10 mm, multiturn shaft, servo mount, for SIDE CONNECTORS | C17: 113 | D17: 8543.90.8885
A18: ='Номенклатура'!A18 -> 575-91004 | B18: ='Номенклатура'!B18 -> DC25FS14 </= 9 min. 3/8" shaft flange side con | C18: 91 | D18: 8543.90.8885
A19: ='Номенклатура'!A19 -> 575-92002 | B19: ='Номенклатура'!B19 -> DC25FE multiturn body 3/8" shaft flange | C19: 91 | D19: 8543.90.8885
A20: ='Номенклатура'!A20 -> DC25-4FS(16) | B20: ='Номенклатура'!B20 -> DC25 housing 4 Speed Side Conn. 3/8" shaft | C20: 91 | D20: 8543.90.8885
A21: ='Номенклатура'!A21 -> H25-FS | B21: ='Номенклатура'!B21 -> Size 25 resolver 3/8 shaft Flange mount side connector 0.95 TR @5000Hz | C21: 91 | D21: 8543.70.4500
A22: ='Номенклатура'!A22 -> 575-93002 | B22: ='Номенклатура'!B22 -> H25 Resolver 5/8" shaft MS-16 end conn. w/o seal Short body | C22: 91 | D22: 8543.90.8885
A23: ='Номенклатура'!A23 -> 575-92011 | B23: ='Номенклатура'!B23 -> DC 25FS Singleturn body 5/8" shaft flange SSI Dura MS23 side conn </= 9min | C23: 91 | D23: 8543.90.8885
A24: ='Номенклатура'!A24 -> 575-91055 | B24: ='Номенклатура'!B24 -> H25-w/ Special servo nose Two flats on shaft TR=0.95 @ 5KHz | C24: 91 | D24: 8543.90.8885
A25: ='Номенклатура'!A25 -> 575-91009 | B25: ='Номенклатура'!B25 -> DC25FS18 </= 9 min 3/8" shaft flange side conn | C25: 91 | D25: 8543.90.8885
... A29: ='Номенклатура'!A29 -> H25-SE-10 | B29: ='Номенклатура'!B29 -> Transducer 1 Turn C&A Flange servo mount with 10mm shaft | C29: 91 | D29: 8543.70.4500
A30: ='Номенклатура'!A30 -> 22140701А | B30: ='Номенклатура'!B30 -> H25 Body with Shaft zeroed for HT-400x-L Single turn TR=1,4, 5KHz,2250Hz w/o conn
A31: ='Номенклатура'!A31 -> 575-91007 | B31: ='Номенклатура'!B31 -> DC25FS16 </=9 min. 3/8" shaft, flange , side conn | C31: 91 | D31: 8543.90.8885
A32: ='Номенклатура'!A32 -> H25-FE-10 | B32: ='Номенклатура'!B32 -> Transducer 1 Turn C&A Flange TR=0.95, 5KHz, w/o conn
A33: ='Номенклатура'!A33 -> H25-SS | B33: ='Номенклатура'!B33 -> Size 25 resolver servo with side connector 0.95 TR@5000Hz 3/8" shaft | C33: 91 | D33: 8543.70.4500
A34: ='Номенклатура'!A34 -> 575-01921 | B34: ='Номенклатура'!B34 -> Resolver size 11, TR=0.5 2500 Hz, Control Transmitter +/- 7min.; 0,12" shaft | C34: 76 | D34: 8543.70.4500
A35: ='Номенклатура'!A35 -> 575-01912-3 | B35: ='Номенклатура'!B35 -> Resolver size 11, TR=0,45 1000Hz, Acc. 3min. Transmitter; 0,12" shaft with flat | C35: 76 | D35: 8543.70.4500
A36: ='Номенклатура'!A36 -> 575-01902 | B36: ='Номенклатура'!B36 -> Resolver size 11, TR-0,95 Transmitter 5KHz; sorted into -1,-4,-8,-10 | C36: 76 | D36: 8543.70.4500
A37: ='Номенклатура'!A37 -> 575-01911-2 | B37: ='Номенклатура'!B37 -> Resolver size 11, TR=,50 2500Hz ACCUR.=<7 with .30" shaft lengt | C37: 76 | D37: 8543.70.4500
A38: ='Номенклатура'!A38 -> 575-01912 | B38: ='Номенклатура'!B38 -> Resolver size 11, TR=0,45 1000Hz, Transmitter Acc. Unsorted | C38: 76 | D38: 8543.70.4500
A39: ='Номенклатура'!A39 -> 575-01924 | B39: ='Номенклатура'!B39 -> Resolver size 11, TR=1,0 1000Hz, control Transmitter +/-7 min | C39: 76 | D39: 8543.70.4500
A40: ='Номенклатура'!A40 -> 575-01920-1 | B40: ='Номенклатура'!B40 -> Resolver size 11, TR=0.45 400Hz,Transmitter w/ flat; Acc.=<7 min. | C40: 76 | D40: 8543.70.4500
A41: ='Номенклатура'!A41 -> 575-01907 | B41: ='Номенклатура'!B41 -> Resolver size 11, TR=1,40 2250Hz | C41: 76 | D41: 8543.70.4500
A42: ='Номенклатура'!A42 -> 575-01909 | B42: ='Номенклатура'!B42 -> Resolver size 11,</=20min TR=0,95 5КHz 2speed | C42: 76 | D42: 8543.70.4500
A43: ='Номенклатура'!A43 -> 575-60025 | B43: ='Номенклатура'!B43 -> NR60 Multiturn Body 3/8" shaft; Nitrile seal Sq. Flange; End conn. | C43: 113 | D43: 8543.90.8885
...

Sheet План
A1: =IFERROR(__xludf.DUMMYFUNCTION("ARRAYFORMULA(IMPORTRANGE(""https://docs.google.com/spreadsheets/d/1iWfgTn_Pi02Cgzvv2hNxbn5R87Czwggoktc9asHRCjo/"",""Разбивка!A1:C1000""))"),"бр.") -> бр. | C1: =IFERROR(__xludf.DUMMYFUNCTION("""COMPUTED_VALUE"""),"Номер") -> Номер | Q1: ARRAYFORMULA(IMPORTRANGE("https://docs.google.com/spreadsheets/d/1iWfgTn_Pi02Cgzvv2hNxbn5R87Czwggoktc9asHRCjo/","Разбивка!A1:C1000"))
A2: =IFERROR(__xludf.DUMMYFUNCTION("""COMPUTED_VALUE"""),100.0) -> 100 | B2: =IFERROR(__xludf.DUMMYFUNCTION("""COMPUTED_VALUE"""),"21100202N") -> 21100202N | C2: =IFERROR(__xludf.DUMMYFUNCTION("""COMPUTED_VALUE"""),"21100202N") -> 21100202N
A3: =IFERROR(__xludf.DUMMYFUNCTION("""COMPUTED_VALUE"""),350.0) -> 350 | B3: =IFERROR(__xludf.DUMMYFUNCTION("""COMPUTED_VALUE"""),2.11137E8) -> 211137000 | C3: =IFERROR(__xludf.DUMMYFUNCTION("""COMPUTED_VALUE"""),2.11137E8) -> 211137000
A4: =IFERROR(__xludf.DUMMYFUNCTION("""COMPUTED_VALUE"""),10.0) -> 10 | B4: =IFERROR(__xludf.DUMMYFUNCTION("""COMPUTED_VALUE"""),2.11279E8) -> 211279000 | C4: =IFERROR(__xludf.DUMMYFUNCTION("""COMPUTED_VALUE"""),2.11279E8) -> 211279000
A5: =IFERROR(__xludf.DUMMYFUNCTION("""COMPUTED_VALUE"""),10.0) -> 10 | B5: =IFERROR(__xludf.DUMMYFUNCTION("""COMPUTED_VALUE"""),"21129500A") -> 21129500A | C5: =IFERROR(__xludf.DUMMYFUNCTION("""COMPUTED_VALUE"""),"21129500A") -> 21129500A
A6: =IFERROR(__xludf.DUMMYFUNCTION("""COMPUTED_VALUE"""),5.0) -> 5 | B6: =IFERROR(__xludf.DUMMYFUNCTION("""COMPUTED_VALUE"""),"21130002D") -> 21130002D | C6: =IFERROR(__xludf.DUMMYFUNCTION("""COMPUTED_VALUE"""),"21130002D") -> 21130002D
A7: =IFERROR(__xludf.DUMMYFUNCTION("""COMPUTED_VALUE"""),175.0) -> 175 | B7: =IFERROR(__xludf.DUMMYFUNCTION("""COMPUTED_VALUE"""),"21134801A") -> 21134801A | C7: =IFERROR(__xludf.DUMMYFUNCTION("""COMPUTED_VALUE"""),"21134801A") -> 21134801A
A8: =IFERROR(__xludf.DUMMYFUNCTION("""COMPUTED_VALUE"""),10.0) -> 10 | B8: =IFERROR(__xludf.DUMMYFUNCTION("""COMPUTED_VALUE"""),2.11361E8) -> 211361000 | C8: =IFERROR(__xludf.DUMMYFUNCTION("""COMPUTED_VALUE"""),2.11361E8) -> 211361000
A9: =IFERROR(__xludf.DUMMYFUNCTION("""COMPUTED_VALUE"""),70.0) -> 70 | B9: =IFERROR(__xludf.DUMMYFUNCTION("""COMPUTED_VALUE"""),"21137200A") -> 21137200A | C9: =IFERROR(__xludf.DUMMYFUNCTION("""COMPUTED_VALUE"""),"21137200A") -> 21137200A
A10: =IFERROR(__xludf.DUMMYFUNCTION("""COMPUTED_VALUE"""),120.0) -> 120 | B10: =IFERROR(__xludf.DUMMYFUNCTION("""COMPUTED_VALUE"""),"21139800A") -> 21139800A | C10: =IFERROR(__xludf.DUMMYFUNCTION("""COMPUTED_VALUE"""),"#N/A") -> #N/A
A11: =IFERROR(__xludf.DUMMYFUNCTION("""COMPUTED_VALUE"""),20.0) -> 20 | B11: =IFERROR(__xludf.DUMMYFUNCTION("""COMPUTED_VALUE"""),2.11404E8) -> 211404000 | C11: =IFERROR(__xludf.DUMMYFUNCTION("""COMPUTED_VALUE"""),2.11404E8) -> 211404000
A12: =IFERROR(__xludf.DUMMYFUNCTION("""COMPUTED_VALUE"""),15.0) -> 15 | B12: =IFERROR(__xludf.DUMMYFUNCTION("""COMPUTED_VALUE"""),"22146701A") -> 22146701A | C12: =IFERROR(__xludf.DUMMYFUNCTION("""COMPUTED_VALUE"""),"22146701A") -> 22146701A
A13: =IFERROR(__xludf.DUMMYFUNCTION("""COMPUTED_VALUE"""),30.0) -> 30 | B13: =IFERROR(__xludf.DUMMYFUNCTION("""COMPUTED_VALUE"""),"575-01902-750") -> 575-01902-750 | C13: =IFERROR(__xludf.DUMMYFUNCTION("""COMPUTED_VALUE"""),"575-01902-750") -> 575-01902-750
A14: =IFERROR(__xludf.DUMMYFUNCTION("""COMPUTED_VALUE"""),120.0) -> 120 | B14: =IFERROR(__xludf.DUMMYFUNCTION("""COMPUTED_VALUE"""),"575-01921") -> 575-01921 | C14: =IFERROR(__xludf.DUMMYFUNCTION("""COMPUTED_VALUE"""),"575-01921") -> 575-01921
A15: =IFERROR(__xludf.DUMMYFUNCTION("""COMPUTED_VALUE"""),35.0) -> 35 | B15: =IFERROR(__xludf.DUMMYFUNCTION("""COMPUTED_VALUE"""),"575-91001") -> 575-91001 | C15: =IFERROR(__xludf.DUMMYFUNCTION("""COMPUTED_VALUE"""),"575-91001") -> 575-91001
A16: =IFERROR(__xludf.DUMMYFUNCTION("""COMPUTED_VALUE"""),20.0) -> 20 | B16: =IFERROR(__xludf.DUMMYFUNCTION("""COMPUTED_VALUE"""),"575-91009") -> 575-91009 | C16: =IFERROR(__xludf.DUMMYFUNCTION("""COMPUTED_VALUE"""),"575-91009") -> 575-91009
A17: =IFERROR(__xludf.DUMMYFUNCTION("""COMPUTED_VALUE"""),10.0) -> 10 | B17: =IFERROR(__xludf.DUMMYFUNCTION("""COMPUTED_VALUE"""),"575-92003") -> 575-92003 | C17: =IFERROR(__xludf.DUMMYFUNCTION("""COMPUTED_VALUE"""),"575-92003") -> 575-92003
A18: =IFERROR(__xludf.DUMMYFUNCTION("""COMPUTED_VALUE"""),20.0) -> 20 | B18: =IFERROR(__xludf.DUMMYFUNCTION("""COMPUTED_VALUE"""),"575-92006") -> 575-92006 | C18: =IFERROR(__xludf.DUMMYFUNCTION("""COMPUTED_VALUE"""),"575-92006") -> 575-92006
A19: =IFERROR(__xludf.DUMMYFUNCTION("""COMPUTED_VALUE"""),10.0) -> 10 | B19: =IFERROR(__xludf.DUMMYFUNCTION("""COMPUTED_VALUE"""),"575-92011") -> 575-92011 | C19: =IFERROR(__xludf.DUMMYFUNCTION("""COMPUTED_VALUE"""),"575-92011") -> 575-92011
A20: =IFERROR(__xludf.DUMMYFUNCTION("""COMPUTED_VALUE"""),100.0) -> 100 | B20: =IFERROR(__xludf.DUMMYFUNCTION("""COMPUTED_VALUE"""),"575-95001") -> 575-95001 | C20: =IFERROR(__xludf.DUMMYFUNCTION("""COMPUTED_VALUE"""),"575-95001") -> 575-95001
A21: =IFERROR(__xludf.DUMMYFUNCTION("""COMPUTED_VALUE"""),100.0) -> 100 | B21: =IFERROR(__xludf.DUMMYFUNCTION("""COMPUTED_VALUE"""),"575-95002") -> 575-95002 | C21: =IFERROR(__xludf.DUMMYFUNCTION("""COMPUTED_VALUE"""),"575-95002") -> 575-95002
A22: =IFERROR(__xludf.DUMMYFUNCTION("""COMPUTED_VALUE"""),100.0) -> 100 | B22: =IFERROR(__xludf.DUMMYFUNCTION("""COMPUTED_VALUE"""),"575-95003") -> 575-95003 | C22: =IFERROR(__xludf.DUMMYFUNCTION("""COMPUTED_VALUE"""),"575-95003") -> 575-95003
A23: =IFERROR(__xludf.DUMMYFUNCTION("""COMPUTED_VALUE"""),100.0) -> 100 | B23: =IFERROR(__xludf.DUMMYFUNCTION("""COMPUTED_VALUE"""),"575-95004") -> 575-95004 | C23: =IFERROR(__xludf.DUMMYFUNCTION("""COMPUTED_VALUE"""),"575-95004") -> 575-95004
A24: =IFERROR(__xludf.DUMMYFUNCTION("""COMPUTED_VALUE"""),2.0) -> 2 | B24: =IFERROR(__xludf.DUMMYFUNCTION("""COMPUTED_VALUE"""),"H25-FS-R2C") -> H25-FS-R2C | C24: =IFERROR(__xludf.DUMMYFUNCTION("""COMPUTED_VALUE"""),"H25-FS-R2C") -> H25-FS-R2C
A25: =IFERROR(__xludf.DUMMYFUNCTION("""COMPUTED_VALUE"""),10.0) -> 10 | B25: =IFERROR(__xludf.DUMMYFUNCTION("""COMPUTED_VALUE"""),"H25-FS-R3N") -> H25-FS-R3N | C25: =IFERROR(__xludf.DUMMYFUNCTION("""COMPUTED_VALUE"""),"H25-FS-R3N") -> H25-FS-R3N
A26: =IFERROR(__xludf.DUMMYFUNCTION("""COMPUTED_VALUE"""),15.0) -> 15 | B26: =IFERROR(__xludf.DUMMYFUNCTION("""COMPUTED_VALUE"""),"H25-SE") -> H25-SE | C26: =IFERROR(__xludf.DUMMYFUNCTION("""COMPUTED_VALUE"""),"H25-SE") -> H25-SE
A27: =IFERROR(__xludf.DUMMYFUNCTION("""COMPUTED_VALUE"""),2.0) -> 2 | B27: =IFERROR(__xludf.DUMMYFUNCTION("""COMPUTED_VALUE"""),"H25V-FE-10") -> H25V-FE-10 | C27: =IFERROR(__xludf.DUMMYFUNCTION("""COMPUTED_VALUE"""),"H25V-FE-10") -> H25V-FE-10
A28: =IFERROR(__xludf.DUMMYFUNCTION("""COMPUTED_VALUE"""),20.0) -> 20 | B28: =IFERROR(__xludf.DUMMYFUNCTION("""COMPUTED_VALUE"""),"575-01910") -> 575-01910 | C28: =IFERROR(__xludf.DUMMYFUNCTION("""COMPUTED_VALUE"""),"575-01910") -> 575-01910
C29: =IFERROR(__xludf.DUMMYFUNCTION("""COMPUTED_VALUE"""),"")
C30: =IFERROR(__xludf.DUMMYFUNCTION("""COMPUTED_VALUE"""),"")
C31: =IFERROR(__xludf.DUMMYFUNCTION("""COMPUTED_VALUE"""),"")
